[2022-11-20 21:24:26,950] {taskinstance.py:1032} INFO - Dependencies all met for <TaskInstance: dag_with_minio_s3_v3.sensor_minio_s3 manual__2022-11-20T21:14:23.524112+00:00 [queued]>
[2022-11-20 21:24:26,963] {taskinstance.py:1032} INFO - Dependencies all met for <TaskInstance: dag_with_minio_s3_v3.sensor_minio_s3 manual__2022-11-20T21:14:23.524112+00:00 [queued]>
[2022-11-20 21:24:26,964] {taskinstance.py:1238} INFO - 
--------------------------------------------------------------------------------
[2022-11-20 21:24:26,965] {taskinstance.py:1239} INFO - Starting attempt 2 of 6
[2022-11-20 21:24:26,965] {taskinstance.py:1240} INFO - 
--------------------------------------------------------------------------------
[2022-11-20 21:24:26,984] {taskinstance.py:1259} INFO - Executing <Task(S3KeySensor): sensor_minio_s3> on 2022-11-20 21:14:23.524112+00:00
[2022-11-20 21:24:26,989] {standard_task_runner.py:52} INFO - Started process 3727 to run task
[2022-11-20 21:24:26,995] {standard_task_runner.py:76} INFO - Running: ['airflow', 'tasks', 'run', 'dag_with_minio_s3_v3', 'sensor_minio_s3', 'manual__2022-11-20T21:14:23.524112+00:00', '--job-id', '11', '--raw', '--subdir', 'DAGS_FOLDER/dag_with_minio_s3.py', '--cfg-path', '/tmp/tmp7qknxqzf', '--error-file', '/tmp/tmpz_nl9or2']
[2022-11-20 21:24:26,997] {standard_task_runner.py:77} INFO - Job 11: Subtask sensor_minio_s3
[2022-11-20 21:24:27,073] {logging_mixin.py:109} INFO - Running <TaskInstance: dag_with_minio_s3_v3.sensor_minio_s3 manual__2022-11-20T21:14:23.524112+00:00 [running]> on host 412505171ea9
[2022-11-20 21:24:27,129] {taskinstance.py:1426} INFO - Exporting the following env vars:
AIRFLOW_CTX_DAG_OWNER=charlie
AIRFLOW_CTX_DAG_ID=dag_with_minio_s3_v3
AIRFLOW_CTX_TASK_ID=sensor_minio_s3
AIRFLOW_CTX_EXECUTION_DATE=2022-11-20T21:14:23.524112+00:00
AIRFLOW_CTX_DAG_RUN_ID=manual__2022-11-20T21:14:23.524112+00:00
[2022-11-20 21:24:27,130] {s3_key.py:96} INFO - Poking for key : s3://airflow/data.csv
[2022-11-20 21:24:27,131] {base_aws.py:401} INFO - Airflow Connection: aws_conn_id=mino_conn
[2022-11-20 21:24:27,140] {base_aws.py:190} INFO - No credentials retrieved from Connection
[2022-11-20 21:24:27,141] {base_aws.py:93} INFO - Creating session with aws_access_key_id=None region_name=None
[2022-11-20 21:24:27,154] {base_aws.py:168} INFO - role_arn is None
[2022-11-20 21:24:27,160] {logging_mixin.py:109} WARNING - /home/airflow/.local/lib/python3.7/site-packages/airflow/providers/amazon/aws/hooks/base_aws.py:494 DeprecationWarning: client_type is deprecated. Set client_type from class attribute.
[2022-11-20 21:24:29,200] {taskinstance.py:1700} ERROR - Task failed with exception
Traceback (most recent call last):
  File "/home/airflow/.local/lib/python3.7/site-packages/airflow/models/taskinstance.py", line 1329, in _run_raw_task
    self._execute_task_with_callbacks(context)
  File "/home/airflow/.local/lib/python3.7/site-packages/airflow/models/taskinstance.py", line 1455, in _execute_task_with_callbacks
    result = self._execute_task(context, self.task)
  File "/home/airflow/.local/lib/python3.7/site-packages/airflow/models/taskinstance.py", line 1511, in _execute_task
    result = execute_callable(context=context)
  File "/home/airflow/.local/lib/python3.7/site-packages/airflow/sensors/base.py", line 234, in execute
    while not self.poke(context):
  File "/home/airflow/.local/lib/python3.7/site-packages/airflow/providers/amazon/aws/sensors/s3_key.py", line 99, in poke
    return self.get_hook().check_for_key(self.bucket_key, self.bucket_name)
  File "/home/airflow/.local/lib/python3.7/site-packages/airflow/providers/amazon/aws/hooks/s3.py", line 62, in wrapper
    return func(*bound_args.args, **bound_args.kwargs)
  File "/home/airflow/.local/lib/python3.7/site-packages/airflow/providers/amazon/aws/hooks/s3.py", line 90, in wrapper
    return func(*bound_args.args, **bound_args.kwargs)
  File "/home/airflow/.local/lib/python3.7/site-packages/airflow/providers/amazon/aws/hooks/s3.py", line 322, in check_for_key
    self.get_conn().head_object(Bucket=bucket_name, Key=key)
  File "/home/airflow/.local/lib/python3.7/site-packages/botocore/client.py", line 388, in _api_call
    return self._make_api_call(operation_name, kwargs)
  File "/home/airflow/.local/lib/python3.7/site-packages/botocore/client.py", line 695, in _make_api_call
    operation_model, request_dict, request_context)
  File "/home/airflow/.local/lib/python3.7/site-packages/botocore/client.py", line 714, in _make_request
    return self._endpoint.make_request(operation_model, request_dict)
  File "/home/airflow/.local/lib/python3.7/site-packages/botocore/endpoint.py", line 102, in make_request
    return self._send_request(request_dict, operation_model)
  File "/home/airflow/.local/lib/python3.7/site-packages/botocore/endpoint.py", line 132, in _send_request
    request = self.create_request(request_dict, operation_model)
  File "/home/airflow/.local/lib/python3.7/site-packages/botocore/endpoint.py", line 116, in create_request
    operation_name=operation_model.name)
  File "/home/airflow/.local/lib/python3.7/site-packages/botocore/hooks.py", line 357, in emit
    return self._emitter.emit(aliased_event_name, **kwargs)
  File "/home/airflow/.local/lib/python3.7/site-packages/botocore/hooks.py", line 228, in emit
    return self._emit(event_name, kwargs)
  File "/home/airflow/.local/lib/python3.7/site-packages/botocore/hooks.py", line 211, in _emit
    response = handler(**kwargs)
  File "/home/airflow/.local/lib/python3.7/site-packages/botocore/signers.py", line 93, in handler
    return self.sign(operation_name, request)
  File "/home/airflow/.local/lib/python3.7/site-packages/botocore/signers.py", line 165, in sign
    auth.add_auth(request)
  File "/home/airflow/.local/lib/python3.7/site-packages/botocore/auth.py", line 378, in add_auth
    raise NoCredentialsError()
botocore.exceptions.NoCredentialsError: Unable to locate credentials
[2022-11-20 21:24:29,212] {taskinstance.py:1277} INFO - Marking task as UP_FOR_RETRY. dag_id=dag_with_minio_s3_v3, task_id=sensor_minio_s3, execution_date=20221120T211423, start_date=20221120T212426, end_date=20221120T212429
[2022-11-20 21:24:29,222] {standard_task_runner.py:92} ERROR - Failed to execute job 11 for task sensor_minio_s3
Traceback (most recent call last):
  File "/home/airflow/.local/lib/python3.7/site-packages/airflow/task/task_runner/standard_task_runner.py", line 85, in _start_by_fork
    args.func(args, dag=self.dag)
  File "/home/airflow/.local/lib/python3.7/site-packages/airflow/cli/cli_parser.py", line 48, in command
    return func(*args, **kwargs)
  File "/home/airflow/.local/lib/python3.7/site-packages/airflow/utils/cli.py", line 92, in wrapper
    return f(*args, **kwargs)
  File "/home/airflow/.local/lib/python3.7/site-packages/airflow/cli/commands/task_command.py", line 298, in task_run
    _run_task_by_selected_method(args, dag, ti)
  File "/home/airflow/.local/lib/python3.7/site-packages/airflow/cli/commands/task_command.py", line 107, in _run_task_by_selected_method
    _run_raw_task(args, ti)
  File "/home/airflow/.local/lib/python3.7/site-packages/airflow/cli/commands/task_command.py", line 184, in _run_raw_task
    error_file=args.error_file,
  File "/home/airflow/.local/lib/python3.7/site-packages/airflow/utils/session.py", line 70, in wrapper
    return func(*args, session=session, **kwargs)
  File "/home/airflow/.local/lib/python3.7/site-packages/airflow/models/taskinstance.py", line 1329, in _run_raw_task
    self._execute_task_with_callbacks(context)
  File "/home/airflow/.local/lib/python3.7/site-packages/airflow/models/taskinstance.py", line 1455, in _execute_task_with_callbacks
    result = self._execute_task(context, self.task)
  File "/home/airflow/.local/lib/python3.7/site-packages/airflow/models/taskinstance.py", line 1511, in _execute_task
    result = execute_callable(context=context)
  File "/home/airflow/.local/lib/python3.7/site-packages/airflow/sensors/base.py", line 234, in execute
    while not self.poke(context):
  File "/home/airflow/.local/lib/python3.7/site-packages/airflow/providers/amazon/aws/sensors/s3_key.py", line 99, in poke
    return self.get_hook().check_for_key(self.bucket_key, self.bucket_name)
  File "/home/airflow/.local/lib/python3.7/site-packages/airflow/providers/amazon/aws/hooks/s3.py", line 62, in wrapper
    return func(*bound_args.args, **bound_args.kwargs)
  File "/home/airflow/.local/lib/python3.7/site-packages/airflow/providers/amazon/aws/hooks/s3.py", line 90, in wrapper
    return func(*bound_args.args, **bound_args.kwargs)
  File "/home/airflow/.local/lib/python3.7/site-packages/airflow/providers/amazon/aws/hooks/s3.py", line 322, in check_for_key
    self.get_conn().head_object(Bucket=bucket_name, Key=key)
  File "/home/airflow/.local/lib/python3.7/site-packages/botocore/client.py", line 388, in _api_call
    return self._make_api_call(operation_name, kwargs)
  File "/home/airflow/.local/lib/python3.7/site-packages/botocore/client.py", line 695, in _make_api_call
    operation_model, request_dict, request_context)
  File "/home/airflow/.local/lib/python3.7/site-packages/botocore/client.py", line 714, in _make_request
    return self._endpoint.make_request(operation_model, request_dict)
  File "/home/airflow/.local/lib/python3.7/site-packages/botocore/endpoint.py", line 102, in make_request
    return self._send_request(request_dict, operation_model)
  File "/home/airflow/.local/lib/python3.7/site-packages/botocore/endpoint.py", line 132, in _send_request
    request = self.create_request(request_dict, operation_model)
  File "/home/airflow/.local/lib/python3.7/site-packages/botocore/endpoint.py", line 116, in create_request
    operation_name=operation_model.name)
  File "/home/airflow/.local/lib/python3.7/site-packages/botocore/hooks.py", line 357, in emit
    return self._emitter.emit(aliased_event_name, **kwargs)
  File "/home/airflow/.local/lib/python3.7/site-packages/botocore/hooks.py", line 228, in emit
    return self._emit(event_name, kwargs)
  File "/home/airflow/.local/lib/python3.7/site-packages/botocore/hooks.py", line 211, in _emit
    response = handler(**kwargs)
  File "/home/airflow/.local/lib/python3.7/site-packages/botocore/signers.py", line 93, in handler
    return self.sign(operation_name, request)
  File "/home/airflow/.local/lib/python3.7/site-packages/botocore/signers.py", line 165, in sign
    auth.add_auth(request)
  File "/home/airflow/.local/lib/python3.7/site-packages/botocore/auth.py", line 378, in add_auth
    raise NoCredentialsError()
botocore.exceptions.NoCredentialsError: Unable to locate credentials
[2022-11-20 21:24:29,244] {local_task_job.py:154} INFO - Task exited with return code 1
[2022-11-20 21:24:29,267] {local_task_job.py:264} INFO - 0 downstream tasks scheduled from follow-on schedule check
